<?xml version="1.0" ?>
<!-- =================================================================================== -->
<!-- |    This document was autogenerated by xacro from /home/sinan/catkin_ws/src/youbot_description/robots/youbot.urdf.xacro | -->
<!-- |    EDITING THIS FILE BY HAND IS NOT RECOMMENDED                                 | -->
<!-- =================================================================================== -->
<robot name="youbot" xmlns:controller="http://playerstage.sourceforge.net/gazebo/xmlschema/#controller" xmlns:interface="http://playerstage.sourceforge.net/gazebo/xmlschema/#interface" xmlns:sensor="http://playerstage.sourceforge.net/gazebo/xmlschema/#sensor">
    &gt;
    <gazebo>
        <plugin filename="libgazebo_ros_control.so" name="gazebo_ros_controller" />
        <plugin name="gazebo_ros_control" filename="libgazebo_ros_control.so">
            <robotNamespace>/</robotNamespace>
        </plugin>
    </gazebo>
    <material name="Orange">
        <color rgba="1.0 0.4 0.0 1.0" />
    </material>
    <material name="Grey">
        <color rgba="0.7 0.7 0.7 1.0" />
    </material>
    <material name="DarkGrey">
        <color rgba="0.3 0.3 0.3 1.0" />
    </material>
    <material name="White">
        <color rgba="1.0 1.0 1.0 1.0" />
    </material>
    <material name="Black">
        <color rgba="0.0 0.0 0.0 1.0" />
    </material>
    <material name="Red">
        <color rgba="1.0 0.0 0.0 1.0" />
    </material>
    <material name="Green">
        <color rgba="0.0 1.0 0.0 1.0" />
    </material>
    <material name="Blue">
        <color rgba="0.0 0.0 0.8 1.0" />
    </material>
    <material name="LightGrey">
        <color rgba="0.82 0.82 0.82 1.0" />
    </material>
    <material name="aluminum">
        <color rgba="0.5 0.5 0.5 1" />
    </material>
    <material name="plastic">
        <color rgba="0.1 0.1 0.1 1" />
    </material>
    <!-- Now we can start using the macros xacro:included above to define the actual youbot -->
    <!-- The first use of a macro.  This one was defined in base.urdf.xacro above.
       A macro like this will expand to a set of link and joint definitions, and to additional
       Gazebo-related extensions (sensor plugins, etc).  The macro takes an argument, name, 
       that equals "base", and uses it to generate names for its component links and joints 
       (e.g., base_link).  The xacro:included origin block is also an argument to the macro.  By convention, 
       the origin block defines where the component is w.r.t its parent (in this case the parent 
       is the world frame). For more, see http://www.ros.org/wiki/xacro -->
    <link name="base_footprint">
        <inertial>
            <mass value="0.1" />
            <origin rpy="0 0 0" xyz="0 0 -0.05" />
            <inertia ixx="1.0" ixy="0.0" ixz="0.0" iyy="1.0" iyz="0.0" izz="1.0" />
        </inertial>
        <visual>
            <origin rpy="0 0 0" xyz="0 0 0" />
            <geometry>
                <box size="0.001 0.001 0.001" />
            </geometry>
            <material name="Red" />
        </visual>
        <collision>
            <origin rpy="0 0 0" xyz="0 0 -0.05" />
            <geometry>
                <box size="0.001 0.001 0.001" />
            </geometry>
        </collision>
    </link>
    <joint name="base_footprint_joint" type="fixed">
        <origin rpy="0 0 0" xyz="0 0 0" />
        <child link="base_link" />
        <parent link="base_footprint" />
    </joint>
    <link name="base_link">
        <inertial>
            <mass value="22.0" />
            <origin xyz="0 0 0" rpy="0 0 0" />
            <inertia ixx="5.652232699207" ixy="-0.009719934438" ixz="1.293988226423" iyy="5.669473158652" iyz="-0.007379583694" izz="3.683196351726" />
        </inertial>
        <visual>
            <origin rpy="0 0 0" xyz="0 0 0" />
            <geometry>
                <mesh filename="package://youbot_description/meshes/youbot_base/base.dae" />
            </geometry>
            <material name="DarkGrey" />
        </visual>
        <collision>
            <origin rpy="0 0 0" xyz="0 0 0" />
            <geometry>
                <!--<box size="${base_size_x} ${base_size_y} ${base_size_z}" />-->
                <mesh filename="package://youbot_description/meshes/youbot_base/base_convex.dae" />
            </geometry>
        </collision>
    </link>
    <!-- front left wheel -->
    <joint name="caster_joint_fl" type="continuous">
        <origin rpy="0 0 0" xyz="0.228 0.158 -0.034" />
        <axis xyz="0 0 1" />
        <limit effort="30" velocity="10" />
        <dynamics damping="1.0" friction="1.0" />
        <safety_controller k_velocity="10.0" />
        <parent link="base_link" />
        <child link="caster_link_fl" />
    </joint>
    <link name="caster_link_fl">
        <inertial>
            <mass value="0.1" />
            <origin xyz="0 0 0" />
            <inertia ixx="0.012411765597" ixy="-0.000711733678" ixz="0.00050272983" iyy="0.015218160428" iyz="-0.000004273467" izz="0.011763977943" />
        </inertial>
    </link>
    <joint name="wheel_joint_fl" type="continuous">
        <axis xyz="0 1 0" />
        <limit effort="30" velocity="10" />
        <origin rpy="0 0 0" xyz="0.0 0.0 0.0" />
        <parent link="caster_link_fl" />
        <dynamics damping="1.0" friction="1.0" />
        <safety_controller k_velocity="10.0" />
        <child link="wheel_link_fl" />
    </joint>
    <link name="wheel_link_fl">
        <inertial>
            <mass value="0.4" />
            <origin xyz="0 0 0" rpy="0 0 0" />
            <inertia ixx="0.012411765597" ixy="-0.000711733678" ixz="0.00050272983" iyy="0.015218160428" iyz="-0.000004273467" izz="0.011763977943" />
        </inertial>
        <visual>
            <origin rpy="0 0 0" xyz="0 0 0" />
            <!--<mesh filename="package://youbot_description/meshes/youbot_base/youbot_wheel.stl" />-->
            <geometry>
                <sphere radius="0.05" />
            </geometry>
            <material name="Orange" />
        </visual>
        <collision>
            <origin rpy="1.5707963267948966 0 0" xyz="0 0 0" />
            <geometry>
                <cylinder length="0.05" radius="0.05" />
            </geometry>
        </collision>
    </link>
    <!-- front right wheel -->
    <joint name="caster_joint_fr" type="continuous">
        <origin rpy="0 0 0" xyz="0.228 -0.158 -0.034" />
        <axis xyz="0 0 1" />
        <limit effort="30" velocity="10" />
        <dynamics damping="1.0" friction="1.0" />
        <safety_controller k_velocity="10.0" />
        <parent link="base_link" />
        <child link="caster_link_fr" />
    </joint>
    <link name="caster_link_fr">
        <inertial>
            <mass value="0.1" />
            <origin xyz="0 0 0" />
            <inertia ixx="0.012411765597" ixy="-0.000711733678" ixz="0.00050272983" iyy="0.015218160428" iyz="-0.000004273467" izz="0.011763977943" />
        </inertial>
    </link>
    <joint name="wheel_joint_fr" type="continuous">
        <axis xyz="0 1 0" />
        <limit effort="30" velocity="10" />
        <dynamics damping="1.0" friction="1.0" />
        <safety_controller k_velocity="10.0" />
        <origin rpy="0 0 0" xyz="0.0 0.0 0.0" />
        <parent link="caster_link_fr" />
        <child link="wheel_link_fr" />
    </joint>
    <link name="wheel_link_fr">
        <inertial>
            <mass value="0.4" />
            <origin xyz="0 0 0" rpy="0 0 0" />
            <inertia ixx="0.012411765597" ixy="-0.000711733678" ixz="0.00050272983" iyy="0.015218160428" iyz="-0.000004273467" izz="0.011763977943" />
        </inertial>
        <visual>
            <origin rpy="0 0 0" xyz="0 0 0" />
            <geometry>
                <!--<mesh filename="package://youbot_description/meshes/youbot_base/youbot_wheel.stl" />-->
                <sphere radius="0.05" />
            </geometry>
            <material name="Orange" />
        </visual>
        <collision>
            <origin rpy="1.5707963267948966 0 0" xyz="0 0 0" />
            <geometry>
                <cylinder length="0.05" radius="0.05" />
            </geometry>
        </collision>
    </link>
    <!-- back left wheel -->
    <joint name="caster_joint_bl" type="continuous">
        <origin rpy="0 0 0" xyz="-0.228 0.158 -0.034" />
        <axis xyz="0 0 1" />
        <limit effort="30" velocity="10" />
        <dynamics damping="1.0" friction="1.0" />
        <safety_controller k_velocity="10.0" />
        <parent link="base_link" />
        <child link="caster_link_bl" />
    </joint>
    <link name="caster_link_bl">
        <inertial>
            <mass value="0.1" />
            <origin xyz="0 0 0" />
            <inertia ixx="0.012411765597" ixy="-0.000711733678" ixz="0.00050272983" iyy="0.015218160428" iyz="-0.000004273467" izz="0.011763977943" />
        </inertial>
    </link>
    <joint name="wheel_joint_bl" type="continuous">
        <axis xyz="0 1 0" />
        <limit effort="10" velocity="10" />
        <limit effort="30" velocity="10" />
        <dynamics damping="1.0" friction="1.0" />
        <safety_controller k_velocity="10.0" />
        <origin rpy="0 0 0" xyz="0.0 0.0 0.0" />
        <parent link="caster_link_bl" />
        <child link="wheel_link_bl" />
    </joint>
    <link name="wheel_link_bl">
        <inertial>
            <mass value="0.4" />
            <origin xyz="0 0 0" rpy="0 0 0" />
            <inertia ixx="0.012411765597" ixy="-0.000711733678" ixz="0.00050272983" iyy="0.015218160428" iyz="-0.000004273467" izz="0.011763977943" />
        </inertial>
        <visual>
            <origin rpy="0 0 0" xyz="0 0 0" />
            <geometry>
                <!--<mesh filename="package://youbot_description/meshes/youbot_base/youbot_wheel.stl" />-->
                <sphere radius="0.05" />
            </geometry>
            <material name="Orange" />
        </visual>
        <collision>
            <origin rpy="1.5707963267948966 0 0" xyz="0 0 0" />
            <geometry>
                <cylinder length="0.05" radius="0.05" />
            </geometry>
        </collision>
    </link>
    <!-- back right wheel -->
    <joint name="caster_joint_br" type="continuous">
        <origin rpy="0 0 0" xyz="-0.228 -0.158 -0.034" />
        <axis xyz="0 0 1" />
        <limit effort="30" velocity="10" />
        <dynamics damping="1.0" friction="1.0" />
        <safety_controller k_velocity="10.0" />
        <parent link="base_link" />
        <child link="caster_link_br" />
    </joint>
    <link name="caster_link_br">
        <inertial>
            <mass value="0.1" />
            <origin xyz="0 0 0" />
            <inertia ixx="0.012411765597" ixy="-0.000711733678" ixz="0.00050272983" iyy="0.015218160428" iyz="-0.000004273467" izz="0.011763977943" />
        </inertial>
    </link>
    <joint name="wheel_joint_br" type="continuous">
        <axis xyz="0 1 0" />
        <limit effort="30" velocity="10" />
        <dynamics damping="1.0" friction="1.0" />
        <safety_controller k_velocity="10.0" />
        <origin rpy="0 0 0" xyz="0.0 0.0 0.0" />
        <parent link="caster_link_br" />
        <child link="wheel_link_br" />
    </joint>
    <link name="wheel_link_br">
        <inertial>
            <mass value="0.4" />
            <origin xyz="0 0 0" rpy="0 0 0" />
            <inertia ixx="0.012411765597" ixy="-0.000711733678" ixz="0.00050272983" iyy="0.015218160428" iyz="-0.000004273467" izz="0.011763977943" />
        </inertial>
        <visual>
            <origin rpy="0 0 0" xyz="0 0 0" />
            <geometry>
                <!--<mesh filename="package://youbot_description/meshes/youbot_base/youbot_wheel.stl" />-->
                <sphere radius="0.05" />
            </geometry>
            <material name="Orange" />
        </visual>
        <collision>
            <origin rpy="1.5707963267948966 0 0" xyz="0 0 0" />
            <geometry>
                <cylinder length="0.05" radius="0.05" />
            </geometry>
        </collision>
    </link>
    <gazebo reference="youbot_base">
        <material value="youbot/DarkGrey" />
    </gazebo>
    <!-- front left wheel -->
    <gazebo reference="wheel_link_fl">
        <material value="youbot/Orange" />
        <kp>1000000</kp>
        <kd>100</kd>
    </gazebo>
    <gazebo reference="caster_link_fl">
        <material value="youbot/Orange" />
    </gazebo>
    <!-- front right wheel -->
    <gazebo reference="wheel_link_fr">
        <material value="youbot/Orange" />
        <kp>1000000</kp>
        <kd>100</kd>
    </gazebo>
    <gazebo reference="caster_link_fr">
        <material value="youbot/Orange" />
    </gazebo>
    <!-- back left wheel -->
    <gazebo reference="wheel_link_bl">
        <material value="youbot/Orange" />
        <kp>1000000</kp>
        <kd>100</kd>
    </gazebo>
    <gazebo reference="caster_link_bl">
        <material value="youbot/Orange" />
    </gazebo>
    <!-- back right wheel -->
    <gazebo reference="wheel_link_br">
        <material value="youbot/Orange" />
        <kp>1000000</kp>
        <kd>100</kd>
    </gazebo>
    <gazebo reference="caster_link_br">
        <material value="youbot/Orange" />
    </gazebo>
    <!-- position controller -->
    <gazebo>
        <plugin filename="libgazebo_ros_planar_move.so" name="base_controller">
            <commandTopic>cmd_vel</commandTopic>
            <odometryTopic>odom</odometryTopic>
            <odometryFrame>odom</odometryFrame>
            <odometryRate>100.0</odometryRate>
            <robotBaseFrame>base_footprint</robotBaseFrame>
        </plugin>
    </gazebo>
    <!-- front left wheel -->
    <transmission name="wheel_trans_fl">
        <type>transmission_interface/SimpleTransmission</type>
        <actuator name="wheel_motor_fl">
            <hardwareInterface>VelocityJointInterface</hardwareInterface>
            <mechanicalReduction>79.23809523809524</mechanicalReduction>
        </actuator>
        <joint name="wheel_joint_fl">
            <hardwareInterface>VelocityJointInterface</hardwareInterface>
        </joint>
    </transmission>
    <transmission name="caster_trans_fl">
        <type>transmission_interface/SimpleTransmission</type>
        <actuator name="caster_motor_fl">
            <hardwareInterface>VelocityJointInterface</hardwareInterface>
            <mechanicalReduction>79.23809523809524</mechanicalReduction>
        </actuator>
        <joint name="caster_joint_fl">
            <hardwareInterface>VelocityJointInterface</hardwareInterface>
        </joint>
    </transmission>
    <!-- front right wheel -->
    <transmission name="wheel_trans_fr">
        <type>transmission_interface/SimpleTransmission</type>
        <actuator name="wheel_motor_fr">
            <hardwareInterface>VelocityJointInterface</hardwareInterface>
            <mechanicalReduction>79.23809523809524</mechanicalReduction>
        </actuator>
        <joint name="wheel_joint_fr">
            <hardwareInterface>VelocityJointInterface</hardwareInterface>
        </joint>
    </transmission>
    <transmission name="caster_trans_fr">
        <type>transmission_interface/SimpleTransmission</type>
        <actuator name="caster_motor_fr">
            <hardwareInterface>VelocityJointInterface</hardwareInterface>
            <mechanicalReduction>79.23809523809524</mechanicalReduction>
        </actuator>
        <joint name="caster_joint_fr">
            <hardwareInterface>VelocityJointInterface</hardwareInterface>
        </joint>
    </transmission>
    <!-- back left wheel -->
    <transmission name="wheel_trans_bl">
        <type>transmission_interface/SimpleTransmission</type>
        <actuator name="wheel_motor_bl">
            <hardwareInterface>VelocityJointInterface</hardwareInterface>
            <mechanicalReduction>79.23809523809524</mechanicalReduction>
        </actuator>
        <joint name="wheel_joint_bl">
            <hardwareInterface>VelocityJointInterface</hardwareInterface>
        </joint>
    </transmission>
    <transmission name="caster_trans_bl">
        <type>transmission_interface/SimpleTransmission</type>
        <actuator name="caster_motor_bl">
            <hardwareInterface>VelocityJointInterface</hardwareInterface>
            <mechanicalReduction>79.23809523809524</mechanicalReduction>
        </actuator>
        <joint name="caster_joint_bl">
            <hardwareInterface>VelocityJointInterface</hardwareInterface>
        </joint>
    </transmission>
    <!-- back right wheel -->
    <transmission name="wheel_trans_br">
        <type>transmission_interface/SimpleTransmission</type>
        <actuator name="wheel_motor_br">
            <hardwareInterface>VelocityJointInterface</hardwareInterface>
            <mechanicalReduction>79.23809523809524</mechanicalReduction>
        </actuator>
        <joint name="wheel_joint_br">
            <hardwareInterface>VelocityJointInterface</hardwareInterface>
        </joint>
    </transmission>
    <transmission name="caster_trans_br">
        <type>transmission_interface/SimpleTransmission</type>
        <actuator name="caster_motor_br">
            <hardwareInterface>VelocityJointInterface</hardwareInterface>
            <mechanicalReduction>79.23809523809524</mechanicalReduction>
        </actuator>
        <joint name="caster_joint_br">
            <hardwareInterface>VelocityJointInterface</hardwareInterface>
        </joint>
    </transmission>
    <!-- joint between arm_7_link and sdh_palm_link -->
    <joint name="plate_joint" type="fixed">
        <origin rpy="0 0 0" xyz="-0.159 0 0.046" />
        <parent link="base_link" />
        <child link="plate_link" />
    </joint>
    <link name="plate_link">
        <inertial>
            <origin rpy="0 0 0" xyz="0 0 0" />
            <mass value="1" />
            <inertia ixx="0.01" ixy="0" ixz="0" iyy="0.01" iyz="0" izz="0.01" />
        </inertial>
        <visual>
            <origin rpy="0 0 0" xyz="0 0 0" />
            <geometry>
                <mesh filename="package://youbot_description/meshes/youbot_plate/plate.dae" />
            </geometry>
            <material name="DarkGrey" />
        </visual>
        <collision>
            <origin rpy="0 0 0" xyz="0 0 0" />
            <geometry>
                <mesh filename="package://youbot_description/meshes/youbot_plate/plate_convex.dae" />
            </geometry>
        </collision>
    </link>
    <!-- extensions -->
    <!-- joint between base_link and arm_0_link -->
    <joint name="arm_joint_0" type="fixed">
        <origin rpy="0 0 0" xyz="0.143 0 0.046" />
        <parent link="base_link" />
        <child link="arm_link_0" />
    </joint>
    <link name="arm_link_0">
        <inertial>
            <!--<origin xyz="0.023 0 0.006" rpy="0 0 0"/>-->
            <origin rpy="0 0 0" xyz="0 0 0" />
            <mass value="0.845" />
            <inertia ixx="0.01" ixy="0" ixz="0" iyy="0.01" iyz="0" izz="0.01" />
        </inertial>
        <visual>
            <origin rpy="0 0 0" xyz="0 0 0" />
            <geometry>
                <mesh filename="package://youbot_description/meshes/youbot_arm/arm0.dae" />
            </geometry>
            <material name="DarkGrey" />
        </visual>
        <collision>
            <!--<origin xyz="0.023 0 0.006" rpy="0 0 0"/>-->
            <origin rpy="0 0 0" xyz="0 0 0" />
            <geometry>
                <mesh filename="package://youbot_description/meshes/youbot_arm/arm0_convex.dae" />
                <!--<cylinder length="0.078" radius="0.093"/>-->
            </geometry>
        </collision>
    </link>
    <!-- joint between arm_0_link and arm_1_link -->
    <joint name="arm_joint_1" type="revolute">
        <origin rpy="0 0 2.9670597283903604" xyz="0.024 0 0.096" />
        <parent link="arm_link_0" />
        <child link="arm_link_1" />
        <axis xyz="0 0 -1" />
        <!--<calibration rising="${arm_1_ref}" falling="${arm_1_ref}"/>-->
        <dynamics damping="1" friction="1" />
        <!-- damping - N*s/m, N*s*m/rad -->
        <!-- friction - N, N*m -->
        <limit effort="9.5" lower="0" upper="5.899212871740834" velocity="1.5707963267948966" />
        <!--effort - N, N*m-->
        <!--velocity - m/s, rad/s-->
        <safety_controller k_position="20" k_velocity="1.5119719593730057" soft_lower_limit="0.001" soft_upper_limit="5.898212871740833" />
        <!--k_position N/m, N/rad-->
        <!--k_velocity N*s/m, N*s*m/rad-->
        <!--for details: http://www.ros.org/wiki/pr2_controller_manager/safety_limits-->
    </joint>
    <link name="arm_link_1">
        <inertial>
            <mass value="2.412" />
            <origin rpy="0 0 0" xyz="0.01489 0.00213 0.00213" />
            <inertia ixx="0.003863" ixy="-0.000979" ixz="0.000000" iyy="0.006196" iyz="0.000000" izz="0.006369" />
        </inertial>
        <visual>
            <origin rpy="0 0 0" xyz="0 0 0" />
            <geometry>
                <mesh filename="package://youbot_description/meshes/youbot_arm/arm1.dae" />
            </geometry>
            <!--<material name="Orange" />-->
        </visual>
        <collision>
            <!--<origin xyz="0 0 -0.003" rpy="0 0 0" />-->
            <origin rpy="0 0 0" xyz="0 0 0" />
            <geometry>
                <mesh filename="package://youbot_description/meshes/youbot_arm/arm1_convex.dae" />
                <!--<cylinder length="0.102" radius="0.080"/>-->
            </geometry>
        </collision>
    </link>
    <!-- joint between arm_1_link and arm_2_link -->
    <joint name="arm_joint_2" type="revolute">
        <origin rpy="0 -1.1344640137963142 0" xyz="0.033 0 0.019" />
        <parent link="arm_link_1" />
        <child link="arm_link_2" />
        <axis xyz="0 1 0" />
        <!--<calibration rising="${arm_2_ref}" falling="${arm_2_ref}"/>-->
        <dynamics damping="1" friction="1" />
        <limit effort="9.5" lower="0" upper="2.705260340591211" velocity="1.5707963267948966" />
        <safety_controller k_position="20" k_velocity="6.047887837492023" soft_lower_limit="0.001" soft_upper_limit="2.704260340591211" />
    </joint>
    <link name="arm_link_2">
        <inertial>
            <mass value="1.155" />
            <origin rpy="0 0 0" xyz="0.10453 0.0017 -0.00297" />
            <inertia ixx="0.000823" ixy="0.000000" ixz="-0.000000" iyy="0.004447" iyz="0.000000" izz="0.004439" />
        </inertial>
        <visual>
            <origin rpy="0 0 0" xyz="0 -0.032 0.078" />
            <geometry>
                <mesh filename="package://youbot_description/meshes/youbot_arm/arm2.dae" />
            </geometry>
            <material name="Orange" />
        </visual>
        <collision>
            <!--<origin xyz="0.001 -0.041 0.074" rpy="0 0 0" />-->
            <origin rpy="0 0 0" xyz="0 -0.032 0.078" />
            <geometry>
                <mesh filename="package://youbot_description/meshes/youbot_arm/arm2_convex.dae" />
                <!--<box size="0.074 0.082 0.222"/>-->
            </geometry>
        </collision>
    </link>
    <!-- joint between arm_2_link and arm_3_link -->
    <!--<joint name="${name}_joint_3" type="revolute">
			<origin xyz="0.000 0.000 0.155" rpy="0 ${146 * M_PI / 180} 0"/>
			<parent link="${name}_link_2"/>
			<child link="${name}_link_3"/>
			<axis xyz="0 1 0"/>
			<dynamics damping="1" friction="1" />
			<limit effort="${6}" velocity="${M_PI / 2.0}" lower="-${joint_3_limit}" upper="0"/>
                        <safety_controller k_position="20" k_velocity="50" soft_lower_limit="-${joint_3_limit_soft}" soft_upper_limit="${threshold}" />
		</joint>-->
    <joint name="arm_joint_3" type="revolute">
        <origin rpy="0 2.548180707911721 0" xyz="0.000 0.000 0.155" />
        <parent link="arm_link_2" />
        <child link="arm_link_3" />
        <axis xyz="0 1 0" />
        <dynamics damping="1" friction="1" />
        <limit effort="6" lower="-5.183627878423159" upper="0" velocity="1.5707963267948966" />
        <safety_controller k_position="20" k_velocity="50" soft_lower_limit="-5.182627878423158" soft_upper_limit="-0.001" />
    </joint>
    <link name="arm_link_3">
        <inertial>
            <mass value="0.934" />
            <origin rpy="0 0 0" xyz="0.0001 0.09670000000000001 0.021070000000000002" />
            <inertia ixx="0.002459" ixy="0.000000" ixz="0.000000" iyy="0.002571" iyz="-0.000000" izz="0.000535" />
        </inertial>
        <visual>
            <origin rpy="0 0 0" xyz="0.000 0.028 0.079" />
            <geometry>
                <mesh filename="package://youbot_description/meshes/youbot_arm/arm3.dae" />
            </geometry>
            <material name="Orange" />
        </visual>
        <collision>
            <!--<origin xyz="0.000 0.025 0.067" rpy="0 0 0" />-->
            <origin rpy="0 0 0" xyz="0.000 0.028 0.079" />
            <geometry>
                <mesh filename="package://youbot_description/meshes/youbot_arm/arm3_convex.dae" />
                <!--<box size="0.064 0.054 0.192"/>-->
            </geometry>
        </collision>
    </link>
    <!-- joint between arm_3_link and arm_4_link -->
    <joint name="arm_joint_4" type="revolute">
        <origin rpy="0 -1.7889624832941877 0" xyz="0.000 0.000 0.135" />
        <parent link="arm_link_3" />
        <child link="arm_link_4" />
        <axis xyz="0 1 0" />
        <!--<calibration rising="${arm_4_ref}" falling="${arm_4_ref}"/>-->
        <dynamics damping="1" friction="1" />
        <limit effort="2" lower="0" upper="3.5779249665883754" velocity="1.5707963267948966" />
        <safety_controller k_position="20" k_velocity="100" soft_lower_limit="0" soft_upper_limit="3.5769249665883756" />
    </joint>
    <link name="arm_link_4">
        <inertial>
            <mass value="0.877" />
            <origin rpy="0 0 0" xyz="0.00011 0.05103 -0.023190000000000002" />
            <inertia ixx="0.000869" ixy="0.000000" ixz="-0.000000" iyy="0.001173" iyz="-0.000231" izz="0.001091" />
        </inertial>
        <visual>
            <origin rpy="0 0 0" xyz="0 -0.010 0.029" />
            <geometry>
                <mesh filename="package://youbot_description/meshes/youbot_arm/arm4.dae" />
            </geometry>
            <material name="Orange" />
        </visual>
        <collision>
            <!--<origin xyz="0 0 0.026" rpy="0 0 0" />-->
            <origin rpy="0 0 0" xyz="0 -0.010 0.029" />
            <geometry>
                <mesh filename="package://youbot_description/meshes/youbot_arm/arm4_convex.dae" />
                <!--<box size="0.058 0.100 0.118"/>-->
            </geometry>
        </collision>
    </link>
    <!-- joint between arm_4_link and arm_5_link -->
    <joint name="arm_joint_5" type="revolute">
        <origin rpy="0 0 2.9234264970905017" xyz="-0.002 0 0.130" />
        <parent link="arm_link_4" />
        <child link="arm_link_5" />
        <axis xyz="0 0 -1" />
        <!--<calibration rising="${arm_5_ref}" falling="${arm_5_ref}"/>-->
        <dynamics damping="1" friction="1" />
        <limit effort="1" lower="0" upper="5.8468529941810035" velocity="1.5707963267948966" />
        <safety_controller k_position="20" k_velocity="100" soft_lower_limit="0" soft_upper_limit="5.845852994181003" />
    </joint>
    <link name="arm_link_5">
        <inertial>
            <mass value="0.251" />
            <origin rpy="0 0 0" xyz="0.0 0.00115 -0.016829999999999998" />
            <inertia ixx="0.000280" ixy="0.000000" ixz="0.000000" iyy="0.000339" iyz="0.000000" izz="0.000119" />
        </inertial>
        <visual>
            <origin rpy="0 0 0" xyz="0.003 0 -0.034" />
            <geometry>
                <mesh filename="package://youbot_description/meshes/youbot_arm/arm5.dae" />
            </geometry>
            <material name="DarkGrey" />
        </visual>
        <collision>
            <origin rpy="0 0 0" xyz="0.003 0 -0.034" />
            <geometry>
                <mesh filename="package://youbot_description/meshes/youbot_arm/arm5_convex.dae" />
                <!--<box size="0.054 0.096 0.030"/>-->
            </geometry>
        </collision>
    </link>
    <gazebo reference="arm_link_0">
        <material value="youbot/DarkGrey" />
        <turnGravityOff>false</turnGravityOff>
    </gazebo>
    <gazebo reference="arm_link_1">
        <!--<material value="youbot/Orange" />-->
        <turnGravityOff>false</turnGravityOff>
    </gazebo>
    <gazebo reference="arm_link_2">
        <!--<material value="youbot/Orange" />-->
        <turnGravityOff>false</turnGravityOff>
    </gazebo>
    <gazebo reference="arm_link_3">
        <!--<material value="youbot/Orange" />-->
        <turnGravityOff>false</turnGravityOff>
    </gazebo>
    <gazebo reference="arm_link_4">
        <!--<material value="youbot/Orange" />-->
        <turnGravityOff>false</turnGravityOff>
    </gazebo>
    <gazebo reference="arm_link_5">
        <!--<material value="youbot/DarkGrey" />-->
        <turnGravityOff>false</turnGravityOff>
    </gazebo>
    <transmission name="arm_trans_1">
        <type>transmission_interface/SimpleTransmission</type>
        <actuator name="arm_motor_1">
            <hardwareInterface>EffortJointInterface</hardwareInterface>
            <mechanicalReduction>1</mechanicalReduction>
        </actuator>
        <joint name="arm_joint_1">
            <hardwareInterface>EffortJointInterface</hardwareInterface>
        </joint>
    </transmission>
    <transmission name="arm_trans_2">
        <type>transmission_interface/SimpleTransmission</type>
        <actuator name="arm_motor_2">
            <hardwareInterface>EffortJointInterface</hardwareInterface>
            <mechanicalReduction>1</mechanicalReduction>
        </actuator>
        <joint name="arm_joint_2">
            <hardwareInterface>EffortJointInterface</hardwareInterface>
        </joint>
    </transmission>
    <transmission name="arm_trans_3">
        <type>transmission_interface/SimpleTransmission</type>
        <actuator name="arm_motor_3">
            <hardwareInterface>EffortJointInterface</hardwareInterface>
            <mechanicalReduction>1</mechanicalReduction>
        </actuator>
        <joint name="arm_joint_3">
            <hardwareInterface>EffortJointInterface</hardwareInterface>
        </joint>
    </transmission>
    <transmission name="arm_trans_4">
        <type>transmission_interface/SimpleTransmission</type>
        <actuator name="arm_motor_4">
            <hardwareInterface>EffortJointInterface</hardwareInterface>
            <mechanicalReduction>1</mechanicalReduction>
        </actuator>
        <joint name="arm_joint_4">
            <hardwareInterface>EffortJointInterface</hardwareInterface>
        </joint>
    </transmission>
    <transmission name="arm_trans_5">
        <type>transmission_interface/SimpleTransmission</type>
        <actuator name="arm_motor_5">
            <hardwareInterface>EffortJointInterface</hardwareInterface>
            <mechanicalReduction>1</mechanicalReduction>
        </actuator>
        <joint name="arm_joint_5">
            <hardwareInterface>EffortJointInterface</hardwareInterface>
        </joint>
    </transmission>
    <!-- joint between arm_7_link and sdh_palm_link -->
    <joint name="gripper_palm_joint" type="fixed">
        <origin rpy="0 0 0" xyz="0 0 0" />
        <parent link="arm_link_5" />
        <child link="gripper_palm_link" />
    </joint>
    <link name="gripper_palm_link">
        <inertial>
            <origin rpy="0 0 0" xyz="0 0 0" />
            <mass value="0.1" />
            <inertia ixx="0.01" ixy="0" ixz="0" iyy="0.01" iyz="0" izz="0.01" />
        </inertial>
        <visual>
            <origin rpy="0 0 0" xyz="0 0 0" />
            <geometry>
                <mesh filename="package://youbot_description/meshes/youbot_gripper/palm.dae" />
            </geometry>
            <material name="Black" />
        </visual>
        <collision>
            <origin rpy="0 0 0" xyz="0 0 0" />
            <geometry>
                <!--<box size="0.050 0.094 0.054"/>-->
                <mesh filename="package://youbot_description/meshes/youbot_gripper/palm_convex.dae" />
            </geometry>
        </collision>
    </link>
    <joint name="gripper_finger_joint_l" type="prismatic">
        <origin rpy="0 0 3.141592653589793" xyz="0.004 0.008 0.046" />
        <parent link="gripper_palm_link" />
        <child link="gripper_finger_link_l" />
        <axis xyz="0 -1 0" />
        <dynamics damping="1.0" friction="1.0" />
        <limit effort="1" lower="0" upper="0.0115" velocity="0.1" />
        <safety_controller k_position="20" k_velocity="25" soft_lower_limit="0.001" soft_upper_limit="0.011" />
    </joint>
    <link name="gripper_finger_link_l">
        <inertial>
            <origin rpy="0 0 0" xyz="0 -0.001 0" />
            <mass value="0.01" />
            <inertia ixx="0.01" ixy="0" ixz="0" iyy="0.01" iyz="0" izz="0.01" />
        </inertial>
        <visual>
            <origin rpy="0 0 0" xyz="0 0 0" />
            <geometry>
                <mesh filename="package://youbot_description/meshes/youbot_gripper/finger.dae" />
            </geometry>
            <material name="Black" />
        </visual>
        <collision>
            <origin rpy="0 0 0" xyz="0 0 0" />
            <geometry>
                <!--<box size="0.014 0.020 0.046"/>-->
                <mesh filename="package://youbot_description/meshes/youbot_gripper/finger_convex.dae" />
            </geometry>
        </collision>
    </link>
    <joint name="gripper_finger_joint_r" type="prismatic">
        <origin rpy="0 0 0" xyz="0.004 -0.008 0.046" />
        <parent link="gripper_palm_link" />
        <child link="gripper_finger_link_r" />
        <axis xyz="0 -1 0" />
        <dynamics damping="1.0" friction="1.0" />
        <limit effort="1" lower="0" upper="0.0115" velocity="0.1" />
        <safety_controller k_position="20" k_velocity="25" soft_lower_limit="0.001" soft_upper_limit="0.011" />
    </joint>
    <link name="gripper_finger_link_r">
        <inertial>
            <origin rpy="0 0 0" xyz="0.000 -0.001 0" />
            <mass value="0.01" />
            <inertia ixx="0.01" ixy="0" ixz="0" iyy="0.01" iyz="0" izz="0.01" />
        </inertial>
        <visual>
            <origin rpy="0 0 0" xyz="0 0 0" />
            <geometry>
                <mesh filename="package://youbot_description/meshes/youbot_gripper/finger.dae" />
            </geometry>
            <material name="Black" />
        </visual>
        <collision>
            <origin rpy="0 0 0" xyz="0.000 0 0" />
            <geometry>
                <!--<box size="0.014 0.020 0.046"/>-->
                <mesh filename="package://youbot_description/meshes/youbot_gripper/finger_convex.dae" />
            </geometry>
        </collision>
    </link>
    <gazebo reference="gripper_palm_link">
        <material>Gazebo/Black</material>
        <turnGravityOff>false</turnGravityOff>
        <selfCollide>true</selfCollide>
    </gazebo>
    <gazebo reference="gripper_finger_l_link">
        <material>Gazebo/Black</material>
        <turnGravityOff>false</turnGravityOff>
        <selfCollide>true</selfCollide>
    </gazebo>
    <gazebo reference="gripper_finger_r_link">
        <material>Gazebo/Black</material>
        <turnGravityOff>false</turnGravityOff>
        <selfCollide>true</selfCollide>
    </gazebo>
    <transmission name="gripper_finger_l_trans">
        <type>transmission_interface/SimpleTransmission</type>
        <actuator name="gripper_finger_l_motor">
            <hardwareInterface>EffortJointInterface</hardwareInterface>
            <mechanicalReduction>1</mechanicalReduction>
        </actuator>
        <joint name="gripper_finger_joint_l">
            <hardwareInterface>EffortJointInterface</hardwareInterface>
        </joint>
    </transmission>
    <transmission name="gripper_finger_r_trans">
        <type>transmission_interface/SimpleTransmission</type>
        <actuator name="gripper_finger_r_motor">
            <hardwareInterface>EffortJointInterface</hardwareInterface>
            <mechanicalReduction>1</mechanicalReduction>
        </actuator>
        <joint name="gripper_finger_joint_r">
            <hardwareInterface>EffortJointInterface</hardwareInterface>
        </joint>
    </transmission>
    <!-- camera body, with origin at bottom screw mount -->
    <joint name="camera_joint" type="fixed">
        <origin rpy="0 -1.5708 0" xyz="-0.01 0 0.02" />
        <parent link="arm_link_5" />
        <child link="camera_bottom_screw_frame" />
    </joint>
    <link name="camera_bottom_screw_frame" />
    <joint name="camera_link_joint" type="fixed">
        <origin rpy="0 0 0" xyz="0.010600000000000002 0.0175 0.0125" />
        <parent link="camera_bottom_screw_frame" />
        <child link="camera_link" />
    </joint>
    <link name="camera_link">
        <visual>
            <!-- the mesh origin is at front plate in between the two infrared camera axes -->
            <origin rpy="1.5707963267948966 0 1.5707963267948966" xyz="0.0043 -0.0175 0" />
            <geometry>
                <mesh filename="package://realsense2_description/meshes/d435.dae" />
            </geometry>
        </visual>
        <collision>
            <origin rpy="0 0 0" xyz="0 -0.0175 0" />
            <geometry>
                <box size="0.02505 0.09 0.025" />
            </geometry>
        </collision>
        <inertial>
            <!-- The following are not reliable values, and should not be used for modeling -->
            <mass value="0.072" />
            <origin xyz="0 0 0" rpy="0 0 0" />
            <inertia ixx="0.003881243" ixy="0.0" ixz="0.0" iyy="0.000498940" iyz="0.0" izz="0.003879257" />
        </inertial>
    </link>
    <!-- camera depth joints and links -->
    <joint name="camera_depth_joint" type="fixed">
        <origin rpy="0 0 0" xyz="0 0 0" />
        <parent link="camera_link" />
        <child link="camera_depth_frame" />
    </joint>
    <link name="camera_depth_frame" />
    <joint name="camera_depth_optical_joint" type="fixed">
        <origin rpy="-1.5707963267948966 0 -1.5707963267948966" xyz="0 0 0" />
        <parent link="camera_depth_frame" />
        <child link="camera_depth_optical_frame" />
    </joint>
    <link name="camera_depth_optical_frame" />
    <!-- camera left IR joints and links -->
    <joint name="camera_infra1_joint" type="fixed">
        <origin rpy="0 0 0" xyz="0 0.0 0" />
        <parent link="camera_link" />
        <child link="camera_infra1_frame" />
    </joint>
    <link name="camera_infra1_frame" />
    <joint name="camera_infra1_optical_joint" type="fixed">
        <origin rpy="-1.5707963267948966 0 -1.5707963267948966" xyz="0 0 0" />
        <parent link="camera_infra1_frame" />
        <child link="camera_infra1_optical_frame" />
    </joint>
    <link name="camera_infra1_optical_frame" />
    <!-- camera right IR joints and links -->
    <joint name="camera_infra2_joint" type="fixed">
        <origin rpy="0 0 0" xyz="0 -0.05 0" />
        <parent link="camera_link" />
        <child link="camera_infra2_frame" />
    </joint>
    <link name="camera_infra2_frame" />
    <joint name="camera_infra2_optical_joint" type="fixed">
        <origin rpy="-1.5707963267948966 0 -1.5707963267948966" xyz="0 0 0" />
        <parent link="camera_infra2_frame" />
        <child link="camera_infra2_optical_frame" />
    </joint>
    <link name="camera_infra2_optical_frame" />
    <!-- camera color joints and links -->
    <joint name="camera_color_joint" type="fixed">
        <origin rpy="0 0 0" xyz="0 0.015 0" />
        <parent link="camera_link" />
        <child link="camera_color_frame" />
    </joint>
    <link name="camera_color_frame" />
    <joint name="camera_color_optical_joint" type="fixed">
        <origin rpy="-1.5707963267948966 0 -1.5707963267948966" xyz="0 0 0" />
        <parent link="camera_color_frame" />
        <child link="camera_color_optical_frame" />
    </joint>
    <link name="camera_color_optical_frame" />
    <joint name="camera_usb_plug_joint" type="fixed">
        <origin rpy="0 0 0" xyz="-0.00605 -0.0528 0" />
        <parent link="camera_link" />
        <child link="camera_usb_plug_link" />
    </joint>
    <link name="camera_usb_plug_link">
        <visual>
            <!-- 0.044850 0.008000 0.018500 -->
            <origin rpy="0 0 1.5707963267948966" xyz="0. -0.022425 0." />
            <geometry>
                <!--box size="0.044850 0.008 0.0185" /-->
                <mesh filename="package://realsense2_description/meshes/plug.stl" />
            </geometry>
            <material name="plastic" />
        </visual>
        <collision>
            <origin rpy="0 0 1.5707963267948966" xyz="0. -0.022425 0." />
            <geometry>
                <!--box size="0.044850 0.008 0.0185" /-->
                <mesh filename="package://realsense2_description/meshes/plug_collision.stl" />
            </geometry>
        </collision>
        <inertial>
            <mass value="0.1" />
            <origin xyz="0 0 0" rpy="0 0 0" />
            <inertia ixx="0.03" iyy="0.03" izz="0.03" ixy="0.0" ixz="0.0" iyz="0.0" />
        </inertial>
    </link>
</robot>

